これ結構長いこと懸案で Object#<=> や coerce で内部的に呼んだメソッドで発生した
例外は無視して false を返すという挙動があって、それをやめて例外をそのまま上に伝
播させようというのが r44453 や r44502 で一度入ったけど、互換性のため警告に留め
るようにして(もう3年くらい前ですね)、r49570 で Object#<=> での比較は例外を発生
させるように変更したのを、do_coerce でも同様に例外を上に伝播させるようにしてい
ます。 [ruby-core:51389] [Feature #7688]
