標準添付ライブラリ timeout の Timeout.timeout のブロック内で ensure 節で明示的に return を呼ぶとタイムアウトがなかったことになって例外が発生しなくなることがあるのを rdoc 用コメントに追記しています。現在の実装では(例外クラスの明示的指定がなかったら)ブロック内の実行でタイムアウト時に例外のかわりに throw による大域脱出をさせるようにしているので rescue での捕捉はできないはずですが、ensure は実行してしまうので return すると errinfo が消えちゃうんですね。 [ruby-core:92882] [Bug #15886]
